File: src/instron_data/rabbet.is_tens_Exports/rabbet_4.csv
Time,Displacement,Force,Tensile displacement,Tensile strain (Displacement),Tensile stress
(s),(mm),(N),(mm),(%),(MPa)
"0.0000","0.0000","0.0110","0.0000","0.0000","0.0001"
"0.0200","0.0004","0.0111","0.0004","0.0004","0.0001"
"0.0400","0.0018","0.0180","0.0018","0.0018","0.0001"
"0.0600","0.0062","0.0327","0.0062","0.0062","0.0003"
"0.0800","0.0137","0.0196","0.0137","0.0138","0.0002"
"0.1000","0.0214","-0.0032","0.0214","0.0215","0.0000"
"0.1200","0.0288","-0.0072","0.0288","0.0289","-0.0001"
"0.1400","0.0367","-0.0132","0.0367","0.0368","-0.0001"
"0.1600","0.0448","-0.0001","0.0448","0.0450","0.0000"
"0.1800","0.0502","-0.0056","0.0502","0.0504","0.0000"
"0.2000","0.0551","-0.0067","0.0551","0.0553","-0.0001"
"0.2200","0.0605","-0.0086","0.0605","0.0607","-0.0001"
"0.2400","0.0664","0.0076","0.0664","0.0667","0.0001"
"0.2600","0.0731","0.0095","0.0731","0.0733","0.0001"
"0.2800","0.0797","0.0155","0.0797","0.0800","0.0001"
"0.3000","0.0866","-0.0049","0.0866","0.0869","0.0000"
"0.3200","0.0947","-0.0035","0.0947","0.0950","0.0000"
"0.3400","0.1015","-0.0044","0.1015","0.1019","0.0000"
"0.3600","0.1072","-0.0081","0.1072","0.1076","-0.0001"
"0.3800","0.1129","-0.0046","0.1129","0.1134","0.0000"
"0.4000","0.1191","0.0106","0.1191","0.1195","0.0001"
"0.4200","0.1259","0.0102","0.1259","0.1263","0.0001"
"0.4400","0.1325","-0.0110","0.1325","0.1330","-0.0001"
"0.4600","0.1394","0.0003","0.1394","0.1399","0.0000"
"0.4800","0.1476","0.0184","0.1476","0.1481","0.0001"
"0.5000","0.1540","-0.0008","0.1540","0.1546","0.0000"
"0.5200","0.1593","-0.0181","0.1593","0.1599","-0.0001"
"0.5400","0.1649","-0.0166","0.1649","0.1655","-0.0001"
"0.5600","0.1712","0.0326","0.1712","0.1718","0.0003"
"0.5800","0.1781","0.2204","0.1781","0.1788","0.0017"
"0.6000","0.1851","0.4738","0.1851","0.1858","0.0037"
"0.6200","0.1928","0.9329","0.1928","0.1935","0.0072"
"0.6400","0.2013","1.6683","0.2013","0.2020","0.0130"
"0.6600","0.2074","2.5056","0.2074","0.2081","0.0195"
"0.6800","0.2128","3.2662","0.2128","0.2136","0.0254"
"0.7000","0.2185","3.9341","0.2185","0.2193","0.0305"
"0.7200","0.2250","4.5805","0.2250","0.2258","0.0356"
"0.7400","0.2319","5.2743","0.2319","0.2327","0.0410"
"0.7600","0.2385","6.0084","0.2385","0.2393","0.0467"
"0.7800","0.2460","6.7941","0.2460","0.2470","0.0528"
"0.8000","0.2543","7.6617","0.2543","0.2552","0.0595"
"0.8200","0.2605","8.5294","0.2605","0.2614","0.0662"
"0.8400","0.2662","9.3091","0.2662","0.2672","0.0723"
"0.8600","0.2721","9.9815","0.2721","0.2731","0.0775"
"0.8800","0.2784","10.6356","0.2784","0.2795","0.0826"
"0.9000","0.2850","11.3264","0.2850","0.2860","0.0879"
"0.9200","0.2914","12.0457","0.2914","0.2925","0.0935"
"0.9400","0.2991","12.7858","0.2991","0.3002","0.0993"
"0.9600","0.3070","13.6134","0.3070","0.3082","0.1057"
"0.9800","0.3129","14.4457","0.3129","0.3141","0.1122"
"1.0000","0.3187","15.1694","0.3187","0.3199","0.1178"
"1.0200","0.3248","15.8315","0.3248","0.3260","0.1229"
"1.0400","0.3314","16.4827","0.3314","0.3327","0.1280"
"1.0600","0.3383","17.2061","0.3383","0.3395","0.1336"
"1.0800","0.3453","17.9614","0.3453","0.3465","0.1395"
"1.1000","0.3536","18.7607","0.3536","0.3550","0.1457"
"1.1200","0.3610","19.6408","0.3610","0.3623","0.1525"
"1.1400","0.3665","20.4514","0.3665","0.3679","0.1588"
"1.1600","0.3721","21.1281","0.3721","0.3735","0.1640"
"1.1800","0.3783","21.7471","0.3783","0.3797","0.1689"
"1.2000","0.3851","22.3915","0.3851","0.3865","0.1739"
"1.2200","0.3918","23.1169","0.3918","0.3933","0.1795"
"1.2400","0.3990","23.8627","0.3990","0.4005","0.1853"
"1.2600","0.4074","24.6490","0.4074","0.4090","0.1914"
"1.2800","0.4143","25.4804","0.4143","0.4159","0.1978"
"1.3000","0.4200","26.2128","0.4200","0.4216","0.2035"
"1.3200","0.4258","26.8138","0.4258","0.4274","0.2082"
"1.3400","0.4323","27.3687","0.4323","0.4339","0.2125"
"1.3600","0.4392","27.9707","0.4392","0.4409","0.2172"
"1.3800","0.4459","28.6112","0.4459","0.4476","0.2221"
"1.4000","0.4531","29.2798","0.4531","0.4548","0.2273"
"1.4200","0.4613","29.9826","0.4613","0.4630","0.2328"
"1.4400","0.4676","30.7098","0.4676","0.4693","0.2384"
"1.4600","0.4731","31.3280","0.4731","0.4748","0.2432"
"1.4800","0.4788","31.8453","0.4788","0.4805","0.2473"
"1.5000","0.4851","32.3604","0.4851","0.4869","0.2513"
"1.5200","0.4918","32.9233","0.4918","0.4936","0.2556"
"1.5400","0.4983","33.5205","0.4983","0.5002","0.2603"
"1.5600","0.5059","34.1461","0.5059","0.5078","0.2651"
"1.5800","0.5144","34.8510","0.5144","0.5163","0.2706"
"1.6000","0.5207","35.5532","0.5207","0.5226","0.2760"
"1.6200","0.5262","36.1478","0.5262","0.5282","0.2807"
"1.6400","0.5321","36.6222","0.5321","0.5341","0.2843"
"1.6600","0.5386","37.0989","0.5386","0.5406","0.2880"
"1.6800","0.5454","37.6272","0.5454","0.5474","0.2922"
"1.7000","0.5525","38.2002","0.5525","0.5545","0.2966"
"1.7200","0.5608","38.8213","0.5608","0.5629","0.3014"
"1.7400","0.5687","39.5189","0.5687","0.5708","0.3068"
"1.7600","0.5743","40.1458","0.5743","0.5764","0.3117"
"1.7800","0.5796","40.6353","0.5796","0.5817","0.3155"
"1.8000","0.5852","41.0343","0.5852","0.5874","0.3186"
"1.8200","0.5917","41.4365","0.5917","0.5939","0.3217"
"1.8400","0.5984","41.9276","0.5984","0.6006","0.3255"
"1.8600","0.6053","42.4615","0.6053","0.6075","0.3297"
"1.8800","0.6133","43.0333","0.6133","0.6156","0.3341"
"1.9000","0.6206","43.6785","0.6206","0.6230","0.3391"
"1.9200","0.6262","44.2729","0.6262","0.6285","0.3438"
"1.9400","0.6320","44.7553","0.6320","0.6344","0.3475"
"1.9600","0.6382","45.2238","0.6382","0.6406","0.3511"
"1.9800","0.6454","45.7304","0.6454","0.6478","0.3551"
"2.0000","0.6523","46.3150","0.6523","0.6547","0.3596"
"2.0200","0.6593","46.9196","0.6593","0.6618","0.3643"
"2.0400","0.6677","47.5703","0.6677","0.6701","0.3694"
"2.0600","0.6745","48.2571","0.6745","0.6770","0.3747"
"2.0800","0.6797","48.8650","0.6797","0.6822","0.3794"
"2.1000","0.6854","49.3402","0.6854","0.6880","0.3831"
"2.1200","0.6916","49.8038","0.6916","0.6942","0.3867"
"2.1400","0.6983","50.3444","0.6983","0.7009","0.3909"
"2.1600","0.7051","50.9468","0.7051","0.7078","0.3956"
"2.1800","0.7125","51.5935","0.7125","0.7152","0.4006"
"2.2000","0.7212","52.3110","0.7212","0.7239","0.4062"
"2.2200","0.7280","53.0725","0.7280","0.7307","0.4121"
"2.2400","0.7337","53.7305","0.7337","0.7364","0.4172"
"2.2600","0.7393","54.2730","0.7393","0.7421","0.4214"
"2.2800","0.7457","54.7829","0.7457","0.7485","0.4254"
"2.3000","0.7526","55.3496","0.7526","0.7554","0.4298"
"2.3200","0.7593","55.9761","0.7593","0.7621","0.4346"
"2.3400","0.7665","56.6205","0.7665","0.7694","0.4396"
"2.3600","0.7745","57.3157","0.7745","0.7774","0.4450"
"2.3800","0.7804","58.0116","0.7804","0.7833","0.4504"
"2.4000","0.7858","58.6030","0.7858","0.7887","0.4550"
"2.4200","0.7915","59.1002","0.7915","0.7944","0.4589"
"2.4400","0.7978","59.6129","0.7978","0.8008","0.4629"
"2.4600","0.8048","60.1901","0.8048","0.8078","0.4673"
"2.4800","0.8120","60.8331","0.8120","0.8150","0.4723"
"2.5000","0.8201","61.5072","0.8201","0.8231","0.4776"
"2.5200","0.8280","62.2480","0.8280","0.8310","0.4833"
"2.5400","0.8336","62.9534","0.8336","0.8367","0.4888"
"2.5600","0.8391","63.5268","0.8391","0.8422","0.4932"
"2.5800","0.8451","64.0159","0.8451","0.8482","0.4970"
"2.6000","0.8520","64.5394","0.8520","0.8551","0.5011"
"2.6200","0.8590","65.1386","0.8590","0.8622","0.5058"
"2.6400","0.8660","65.7794","0.8660","0.8692","0.5107"
"2.6600","0.8743","66.4489","0.8743","0.8775","0.5159"
"2.6800","0.8817","67.1915","0.8817","0.8849","0.5217"
"2.7000","0.8871","67.8355","0.8871","0.8904","0.5267"
"2.7200","0.8925","68.3372","0.8925","0.8958","0.5306"
"2.7400","0.8982","68.7775","0.8982","0.9016","0.5340"
"2.7600","0.9046","69.2482","0.9046","0.9080","0.5377"
"2.7800","0.9111","69.8239","0.9111","0.9145","0.5421"
"2.8000","0.9180","70.4530","0.9180","0.9214","0.5470"
"2.8200","0.9263","71.1661","0.9263","0.9298","0.5526"
"2.8400","0.9338","71.9898","0.9338","0.9373","0.5590"
"2.8600","0.9395","72.7512","0.9395","0.9430","0.5649"
"2.8800","0.9452","73.3606","0.9452","0.9487","0.5696"
"2.9000","0.9515","73.9186","0.9515","0.9550","0.5739"
"2.9200","0.9588","74.5193","0.9588","0.9623","0.5786"
"2.9400","0.9660","75.2299","0.9660","0.9696","0.5841"
"2.9600","0.9733","75.9789","0.9733","0.9769","0.5899"
"2.9800","0.9816","76.7539","0.9816","0.9853","0.5959"
"3.0000","0.9878","77.5489","0.9878","0.9915","0.6021"
"3.0200","0.9927","78.1898","0.9927","0.9964","0.6071"
"3.0400","0.9982","78.6844","0.9982","1.0019","0.6109"
"3.0600","1.0046","79.1753","1.0046","1.0083","0.6147"
"3.0800","1.0115","79.7526","1.0115","1.0152","0.6192"
"3.0880","1.0142","80.0072","1.0142","1.0179","0.6212"