File: src/instron_data/dovetail.is_tens_Exports/dovetail_6.csv
Time,Displacement,Force,Tensile displacement,Tensile strain (Displacement),Tensile stress
(s),(mm),(N),(mm),(%),(MPa)
"0.0000","0.0000","0.0171","0.0000","0.0000","0.0001"
"0.0200","0.0004","0.0232","0.0004","0.0004","0.0002"
"0.0400","0.0015","0.0515","0.0015","0.0017","0.0004"
"0.0600","0.0057","0.1708","0.0057","0.0063","0.0013"
"0.0800","0.0132","0.4871","0.0132","0.0147","0.0038"
"0.1000","0.0190","0.9316","0.0190","0.0211","0.0072"
"0.1200","0.0246","1.2036","0.0246","0.0274","0.0093"
"0.1400","0.0311","1.3397","0.0311","0.0346","0.0104"
"0.1600","0.0388","1.3887","0.0388","0.0432","0.0108"
"0.1800","0.0462","1.4384","0.0462","0.0514","0.0112"
"0.2000","0.0537","1.5236","0.0537","0.0597","0.0118"
"0.2200","0.0616","1.6203","0.0616","0.0685","0.0126"
"0.2400","0.0676","1.6770","0.0676","0.0752","0.0130"
"0.2600","0.0729","1.7329","0.0729","0.0811","0.0135"
"0.2800","0.0783","1.7458","0.0783","0.0871","0.0136"
"0.3000","0.0843","1.7253","0.0843","0.0938","0.0134"
"0.3200","0.0910","1.7049","0.0910","0.1012","0.0132"
"0.3400","0.0976","1.6916","0.0976","0.1085","0.0131"
"0.3600","0.1049","1.7665","0.1049","0.1166","0.0137"
"0.3800","0.1133","1.8569","0.1133","0.1260","0.0144"
"0.4000","0.1199","1.9364","0.1199","0.1333","0.0150"
"0.4200","0.1255","1.9923","0.1255","0.1396","0.0155"
"0.4400","0.1312","2.0391","0.1312","0.1459","0.0158"
"0.4600","0.1376","2.0281","0.1376","0.1531","0.0157"
"0.4800","0.1445","2.0260","0.1445","0.1607","0.0157"
"0.5000","0.1513","2.0175","0.1513","0.1683","0.0157"
"0.5200","0.1590","2.0277","0.1590","0.1768","0.0157"
"0.5400","0.1672","2.0545","0.1672","0.1860","0.0160"
"0.5600","0.1731","2.0753","0.1731","0.1925","0.0161"
"0.5800","0.1785","2.1306","0.1785","0.1985","0.0165"
"0.6000","0.1843","2.1929","0.1843","0.2050","0.0170"
"0.6200","0.1908","2.2246","0.1908","0.2122","0.0173"
"0.6400","0.1977","2.2120","0.1977","0.2198","0.0172"
"0.6600","0.2046","2.1912","0.2046","0.2275","0.0170"
"0.6800","0.2128","2.1708","0.2128","0.2367","0.0169"
"0.7000","0.2209","2.1650","0.2209","0.2457","0.0168"
"0.7200","0.2266","2.1912","0.2266","0.2520","0.0170"
"0.7400","0.2323","2.2826","0.2323","0.2584","0.0177"
"0.7600","0.2384","2.3936","0.2384","0.2652","0.0186"
"0.7800","0.2453","2.4910","0.2453","0.2728","0.0193"
"0.8000","0.2520","2.5473","0.2520","0.2803","0.0198"
"0.8200","0.2585","2.5890","0.2585","0.2875","0.0201"
"0.8400","0.2662","2.6207","0.2662","0.2960","0.0203"
"0.8600","0.2733","2.6191","0.2733","0.3039","0.0203"
"0.8800","0.2788","2.6210","0.2788","0.3101","0.0204"
"0.9000","0.2844","2.6580","0.2844","0.3163","0.0206"
"0.9200","0.2905","2.7704","0.2905","0.3231","0.0215"
"0.9400","0.2975","3.0095","0.2975","0.3308","0.0234"
"0.9600","0.3045","3.4022","0.3045","0.3386","0.0264"
"0.9800","0.3117","3.8675","0.3117","0.3467","0.0300"
"1.0000","0.3203","4.3777","0.3203","0.3562","0.0340"
"1.0200","0.3271","4.9066","0.3271","0.3637","0.0381"
"1.0400","0.3326","5.3898","0.3326","0.3699","0.0418"
"1.0600","0.3384","5.8066","0.3384","0.3763","0.0451"
"1.0800","0.3447","6.2246","0.3447","0.3834","0.0483"
"1.1000","0.3516","6.6814","0.3516","0.3910","0.0519"
"1.1200","0.3584","7.1797","0.3584","0.3986","0.0557"
"1.1400","0.3657","7.7304","0.3657","0.4067","0.0600"
"1.1600","0.3739","8.3521","0.3739","0.4158","0.0648"
"1.1800","0.3799","8.9755","0.3799","0.4225","0.0697"
"1.2000","0.3854","9.5294","0.3854","0.4286","0.0740"
"1.2200","0.3912","10.0214","0.3912","0.4351","0.0778"
"1.2400","0.3976","10.5007","0.3976","0.4421","0.0815"
"1.2600","0.4043","11.0043","0.4043","0.4496","0.0854"
"1.2800","0.4111","11.5396","0.4111","0.4571","0.0896"
"1.3000","0.4187","12.1022","0.4187","0.4657","0.0940"
"1.3200","0.4272","12.7605","0.4272","0.4751","0.0991"
"1.3400","0.4335","13.4561","0.4335","0.4821","0.1045"
"1.3600","0.4391","14.0576","0.4391","0.4883","0.1091"
"1.3800","0.4450","14.5998","0.4450","0.4949","0.1134"
"1.4000","0.4519","15.1265","0.4519","0.5025","0.1174"
"1.4200","0.4588","15.7118","0.4588","0.5102","0.1220"
"1.4400","0.4654","16.3356","0.4654","0.5175","0.1268"
"1.4600","0.4730","16.9979","0.4730","0.5260","0.1320"
"1.4800","0.4803","17.7307","0.4803","0.5341","0.1377"
"1.5000","0.4858","18.4082","0.4858","0.5402","0.1429"
"1.5200","0.4914","18.9759","0.4914","0.5465","0.1473"
"1.5400","0.4976","19.5177","0.4976","0.5534","0.1515"
"1.5600","0.5043","20.0930","0.5043","0.5609","0.1560"
"1.5800","0.5115","20.7143","0.5115","0.5688","0.1608"
"1.6000","0.5191","21.3907","0.5191","0.5773","0.1661"
"1.6200","0.5278","22.1823","0.5278","0.5870","0.1722"
"1.6400","0.5350","23.1272","0.5350","0.5950","0.1796"
"1.6600","0.5404","24.0016","0.5404","0.6010","0.1864"
"1.6800","0.5456","24.7080","0.5456","0.6068","0.1918"
"1.7000","0.5514","25.3759","0.5514","0.6132","0.1970"
"1.7200","0.5581","26.1400","0.5581","0.6207","0.2030"
"1.7400","0.5649","27.0306","0.5649","0.6283","0.2099"
"1.7600","0.5719","27.9757","0.5719","0.6361","0.2172"
"1.7800","0.5801","28.9841","0.5801","0.6451","0.2250"
"1.8000","0.5868","30.0657","0.5868","0.6525","0.2334"
"1.8200","0.5919","30.9856","0.5919","0.6583","0.2406"
"1.8400","0.5974","31.7435","0.5974","0.6644","0.2465"
"1.8600","0.6037","32.5088","0.6037","0.6714","0.2524"
"1.8800","0.6109","33.3897","0.6109","0.6794","0.2592"
"1.9000","0.6181","34.4028","0.6181","0.6874","0.2671"
"1.9200","0.6257","35.4667","0.6257","0.6958","0.2754"
"1.9400","0.6340","36.6057","0.6340","0.7051","0.2842"
"1.9600","0.6405","37.7489","0.6405","0.7123","0.2931"
"1.9800","0.6461","38.7051","0.6461","0.7185","0.3005"
"2.0000","0.6518","39.4952","0.6518","0.7249","0.3067"
"2.0200","0.6584","40.2859","0.6584","0.7322","0.3128"
"2.0400","0.6654","41.1982","0.6654","0.7400","0.3199"
"2.0600","0.6720","42.1733","0.6720","0.7473","0.3274"
"2.0800","0.6794","43.1385","0.6794","0.7555","0.3349"
"2.1000","0.6874","44.2067","0.6874","0.7645","0.3432"
"2.1200","0.6934","45.2668","0.6934","0.7711","0.3515"
"2.1400","0.6988","46.1091","0.6988","0.7772","0.3580"
"2.1600","0.7046","46.8558","0.7046","0.7836","0.3638"
"2.1800","0.7108","47.6241","0.7108","0.7905","0.3698"
"2.2000","0.7174","48.4859","0.7174","0.7978","0.3765"
"2.2200","0.7242","49.4177","0.7242","0.8054","0.3837"
"2.2400","0.7322","50.4074","0.7322","0.8142","0.3914"
"2.2600","0.7404","51.5261","0.7404","0.8234","0.4001"
"2.2800","0.7463","52.5999","0.7463","0.8300","0.4084"
"2.3000","0.7520","53.4227","0.7520","0.8363","0.4148"
"2.3200","0.7578","54.1411","0.7578","0.8428","0.4204"
"2.3400","0.7646","54.9073","0.7646","0.8503","0.4263"
"2.3600","0.7717","55.8175","0.7717","0.8582","0.4334"
"2.3800","0.7787","56.8056","0.7787","0.8660","0.4411"
"2.4000","0.7869","57.8517","0.7869","0.8751","0.4492"
"2.4200","0.7942","59.0245","0.7942","0.8832","0.4583"
"2.4400","0.7994","60.0470","0.7994","0.8890","0.4662"
"2.4600","0.8048","60.8283","0.8048","0.8950","0.4723"
"2.4800","0.8107","61.5774","0.8107","0.9016","0.4781"
"2.5000","0.8176","62.4562","0.8176","0.9093","0.4849"
"2.5200","0.8247","63.4795","0.8247","0.9172","0.4929"
"2.5400","0.8321","64.5781","0.8321","0.9254","0.5014"
"2.5600","0.8407","65.7571","0.8407","0.9350","0.5106"
"2.5800","0.8480","67.0231","0.8480","0.9430","0.5204"
"2.6000","0.8537","68.1019","0.8537","0.9494","0.5288"
"2.6200","0.8593","68.9447","0.8593","0.9556","0.5353"
"2.6400","0.8652","69.7201","0.8652","0.9622","0.5413"
"2.6600","0.8717","70.5645","0.8717","0.9694","0.5479"
"2.6800","0.8781","71.4822","0.8781","0.9765","0.5550"
"2.7000","0.8849","72.4298","0.8849","0.9841","0.5624"
"2.7200","0.8929","73.4805","0.8929","0.9930","0.5705"
"2.7400","0.8997","74.6295","0.8997","1.0006","0.5795"
"2.7600","0.9053","75.6169","0.9053","1.0068","0.5871"
"2.7800","0.9113","76.4148","0.9113","1.0134","0.5933"
"2.8000","0.9177","77.2302","0.9177","1.0206","0.5996"
"2.8200","0.9245","78.1422","0.9245","1.0282","0.6067"
"2.8400","0.9314","79.1285","0.9314","1.0358","0.6144"
"2.8580","0.9381","80.0397","0.9381","1.0433","0.6215"