File: src/instron_data/scarf.is_tens_Exports/scarf_5.csv
Time,Displacement,Force,Tensile displacement,Tensile strain (Displacement),Tensile stress
(s),(mm),(N),(mm),(%),(MPa)
"0.0000","0.0000","0.0116","0.0000","0.0000","0.0001"
"0.0200","0.0004","0.0126","0.0004","0.0003","0.0001"
"0.0400","0.0019","0.0055","0.0019","0.0015","0.0000"
"0.0600","0.0067","0.0302","0.0067","0.0051","0.0002"
"0.0800","0.0140","0.0261","0.0140","0.0108","0.0002"
"0.1000","0.0214","0.0013","0.0214","0.0165","0.0000"
"0.1200","0.0290","-0.0182","0.0290","0.0223","-0.0001"
"0.1400","0.0364","0.0011","0.0364","0.0280","0.0000"
"0.1600","0.0443","0.0044","0.0443","0.0341","0.0000"
"0.1800","0.0515","-0.0194","0.0515","0.0396","-0.0002"
"0.2000","0.0565","-0.0173","0.0565","0.0435","-0.0001"
"0.2200","0.0615","0.0065","0.0615","0.0473","0.0001"
"0.2400","0.0669","0.0070","0.0669","0.0515","0.0001"
"0.2600","0.0730","-0.0027","0.0730","0.0562","0.0000"
"0.2800","0.0797","-0.0007","0.0797","0.0614","0.0000"
"0.3000","0.0863","0.0129","0.0863","0.0665","0.0001"
"0.3200","0.0940","0.0086","0.0940","0.0723","0.0001"
"0.3400","0.1022","-0.0108","0.1022","0.0787","-0.0001"
"0.3600","0.1083","-0.0089","0.1083","0.0834","-0.0001"
"0.3800","0.1140","0.0117","0.1140","0.0877","0.0001"
"0.4000","0.1196","0.0363","0.1196","0.0921","0.0003"
"0.4200","0.1259","0.0646","0.1259","0.0969","0.0005"
"0.4400","0.1327","0.0910","0.1327","0.1021","0.0007"
"0.4600","0.1395","0.1089","0.1395","0.1074","0.0008"
"0.4800","0.1472","0.1259","0.1472","0.1133","0.0010"
"0.5000","0.1552","0.1482","0.1552","0.1194","0.0012"
"0.5200","0.1610","0.1697","0.1610","0.1239","0.0013"
"0.5400","0.1663","0.1715","0.1663","0.1280","0.0013"
"0.5600","0.1720","0.1899","0.1720","0.1324","0.0015"
"0.5800","0.1785","0.3010","0.1785","0.1374","0.0023"
"0.6000","0.1856","0.4723","0.1856","0.1429","0.0037"
"0.6200","0.1926","0.7637","0.1926","0.1483","0.0059"
"0.6400","0.2007","1.1382","0.2007","0.1545","0.0088"
"0.6600","0.2081","1.5479","0.2081","0.1602","0.0120"
"0.6800","0.2132","1.9122","0.2132","0.1641","0.0148"
"0.7000","0.2187","2.2136","0.2187","0.1684","0.0172"
"0.7200","0.2250","2.4819","0.2250","0.1732","0.0193"
"0.7400","0.2322","2.7997","0.2322","0.1787","0.0217"
"0.7600","0.2395","3.1595","0.2395","0.1843","0.0245"
"0.7800","0.2471","3.5274","0.2471","0.1902","0.0274"
"0.8000","0.2554","3.9070","0.2554","0.1966","0.0303"
"0.8200","0.2620","4.2203","0.2620","0.2016","0.0328"
"0.8400","0.2672","4.3799","0.2672","0.2057","0.0340"
"0.8600","0.2726","4.4700","0.2726","0.2099","0.0347"
"0.8800","0.2786","4.6302","0.2786","0.2144","0.0360"
"0.9000","0.2851","4.8636","0.2851","0.2195","0.0378"
"0.9200","0.2918","5.1543","0.2918","0.2246","0.0400"
"0.9400","0.2989","5.4750","0.2989","0.2300","0.0425"
"0.9600","0.3074","5.8420","0.3074","0.2366","0.0454"
"0.9800","0.3145","6.2177","0.3145","0.2421","0.0483"
"1.0000","0.3200","6.5757","0.3200","0.2463","0.0511"
"1.0200","0.3257","6.9019","0.3257","0.2507","0.0536"
"1.0400","0.3319","7.2548","0.3319","0.2555","0.0563"
"1.0600","0.3389","7.6545","0.3389","0.2608","0.0594"
"1.0800","0.3459","8.1301","0.3459","0.2662","0.0631"
"1.1000","0.3535","8.6399","0.3535","0.2721","0.0671"
"1.1200","0.3619","9.2193","0.3619","0.2785","0.0716"
"1.1400","0.3681","9.8068","0.3681","0.2833","0.0761"
"1.1600","0.3735","10.2943","0.3735","0.2875","0.0799"
"1.1800","0.3790","10.7253","0.3790","0.2917","0.0833"
"1.2000","0.3854","11.1726","0.3854","0.2966","0.0867"
"1.2200","0.3923","11.7036","0.3923","0.3020","0.0909"
"1.2400","0.3992","12.3139","0.3992","0.3073","0.0956"
"1.2600","0.4071","12.9741","0.4071","0.3134","0.1007"
"1.2800","0.4154","13.6880","0.4154","0.3198","0.1063"
"1.3000","0.4214","14.3975","0.4214","0.3244","0.1118"
"1.3200","0.4270","14.9774","0.4270","0.3287","0.1163"
"1.3400","0.4329","15.4730","0.4329","0.3332","0.1201"
"1.3600","0.4395","15.9967","0.4395","0.3383","0.1242"
"1.3800","0.4463","16.5957","0.4463","0.3435","0.1289"
"1.4000","0.4527","17.2279","0.4527","0.3484","0.1338"
"1.4200","0.4601","17.8686","0.4601","0.3542","0.1387"
"1.4400","0.4675","18.5695","0.4675","0.3598","0.1442"
"1.4600","0.4731","19.2367","0.4731","0.3641","0.1494"
"1.4800","0.4788","19.8027","0.4788","0.3685","0.1538"
"1.5000","0.4850","20.3250","0.4850","0.3733","0.1578"
"1.5200","0.4919","20.8872","0.4919","0.3786","0.1622"
"1.5400","0.4991","21.5137","0.4991","0.3842","0.1670"
"1.5600","0.5065","22.1668","0.5065","0.3898","0.1721"
"1.5800","0.5149","22.8481","0.5149","0.3963","0.1774"
"1.6000","0.5221","23.5941","0.5221","0.4019","0.1832"
"1.6200","0.5276","24.2378","0.5276","0.4061","0.1882"
"1.6400","0.5331","24.7354","0.5331","0.4103","0.1921"
"1.6600","0.5392","25.1775","0.5392","0.4150","0.1955"
"1.6800","0.5458","25.6603","0.5458","0.4201","0.1992"
"1.7000","0.5523","26.1935","0.5523","0.4251","0.2034"
"1.7200","0.5594","26.7415","0.5594","0.4306","0.2076"
"1.7400","0.5680","27.3533","0.5680","0.4372","0.2124"
"1.7600","0.5749","28.0082","0.5749","0.4425","0.2175"
"1.7800","0.5803","28.5441","0.5803","0.4466","0.2216"
"1.8000","0.5857","28.9247","0.5857","0.4509","0.2246"
"1.8200","0.5920","29.2820","0.5920","0.4556","0.2274"
"1.8400","0.5989","29.6948","0.5989","0.4610","0.2306"
"1.8600","0.6057","30.1830","0.6057","0.4662","0.2344"
"1.8800","0.6132","30.6919","0.6132","0.4720","0.2383"
"1.9000","0.6216","31.2671","0.6216","0.4784","0.2428"
"1.9200","0.6275","31.8481","0.6275","0.4830","0.2473"
"1.9400","0.6329","32.3389","0.6329","0.4871","0.2511"
"1.9600","0.6387","32.7508","0.6387","0.4916","0.2543"
"1.9800","0.6453","33.1687","0.6453","0.4967","0.2575"
"2.0000","0.6526","33.6526","0.6526","0.5023","0.2613"
"2.0200","0.6598","34.1598","0.6598","0.5079","0.2652"
"2.0400","0.6676","34.6774","0.6676","0.5138","0.2692"
"2.0600","0.6753","35.2312","0.6753","0.5198","0.2735"
"2.0800","0.6810","35.7321","0.6810","0.5242","0.2774"
"2.1000","0.6864","36.1059","0.6864","0.5283","0.2803"
"2.1200","0.6923","36.4395","0.6923","0.5329","0.2829"
"2.1400","0.6990","36.8195","0.6990","0.5380","0.2859"
"2.1600","0.7061","37.3127","0.7061","0.5435","0.2897"
"2.1800","0.7130","37.8508","0.7130","0.5488","0.2939"
"2.2000","0.7210","38.3912","0.7210","0.5550","0.2981"
"2.2200","0.7290","39.0068","0.7290","0.5611","0.3029"
"2.2400","0.7349","39.5728","0.7349","0.5656","0.3073"
"2.2600","0.7406","39.9919","0.7406","0.5700","0.3105"
"2.2800","0.7464","40.3521","0.7464","0.5745","0.3133"
"2.3000","0.7526","40.7353","0.7526","0.5793","0.3163"
"2.3200","0.7589","41.1830","0.7589","0.5841","0.3198"
"2.3400","0.7654","41.6813","0.7654","0.5891","0.3236"
"2.3600","0.7734","42.2413","0.7734","0.5953","0.3280"
"2.3800","0.7813","42.9426","0.7813","0.6013","0.3334"
"2.4000","0.7870","43.6102","0.7870","0.6057","0.3386"
"2.4200","0.7923","44.1308","0.7923","0.6099","0.3426"
"2.4400","0.7981","44.5633","0.7981","0.6143","0.3460"
"2.4600","0.8049","45.0440","0.8049","0.6195","0.3497"
"2.4800","0.8121","45.6338","0.8121","0.6250","0.3543"
"2.5000","0.8194","46.3209","0.8194","0.6307","0.3597"
"2.5200","0.8281","47.0582","0.8281","0.6374","0.3654"
"2.5400","0.8350","47.8592","0.8350","0.6427","0.3716"
"2.5600","0.8403","48.5194","0.8403","0.6468","0.3767"
"2.5800","0.8460","49.0053","0.8460","0.6511","0.3805"
"2.6000","0.8523","49.4550","0.8523","0.6560","0.3840"
"2.6200","0.8593","49.9982","0.8593","0.6614","0.3882"
"2.6400","0.8664","50.6490","0.8664","0.6669","0.3933"
"2.6600","0.8742","51.3722","0.8742","0.6728","0.3989"
"2.6800","0.8820","52.1845","0.8820","0.6789","0.4052"
"2.7000","0.8878","52.9727","0.8878","0.6833","0.4113"
"2.7200","0.8931","53.5871","0.8931","0.6874","0.4161"
"2.7400","0.8989","54.1010","0.8989","0.6919","0.4201"
"2.7600","0.9054","54.6346","0.9054","0.6969","0.4242"
"2.7800","0.9125","55.2763","0.9125","0.7024","0.4292"
"2.8000","0.9192","55.9931","0.9192","0.7075","0.4348"
"2.8200","0.9264","56.7091","0.9264","0.7131","0.4403"
"2.8400","0.9347","57.4764","0.9347","0.7194","0.4463"
"2.8600","0.9408","58.2717","0.9408","0.7241","0.4524"
"2.8800","0.9463","58.9188","0.9463","0.7284","0.4575"
"2.9000","0.9522","59.4414","0.9522","0.7329","0.4615"
"2.9200","0.9588","59.9777","0.9588","0.7380","0.4657"
"2.9400","0.9658","60.6126","0.9658","0.7434","0.4706"
"2.9600","0.9727","61.3086","0.9727","0.7487","0.4760"
"2.9800","0.9805","62.0517","0.9805","0.7547","0.4818"
"3.0000","0.9886","62.8629","0.9886","0.7609","0.4881"
"3.0200","0.9946","63.6564","0.9946","0.7655","0.4943"
"3.0400","1.0002","64.2959","1.0002","0.7698","0.4992"
"3.0600","1.0061","64.8330","1.0061","0.7744","0.5034"
"3.0800","1.0130","65.3781","1.0130","0.7797","0.5076"
"3.1000","1.0200","66.0415","1.0200","0.7851","0.5128"
"3.1200","1.0270","66.7584","1.0270","0.7905","0.5183"
"3.1400","1.0351","67.5074","1.0351","0.7967","0.5242"
"3.1600","1.0420","68.3270","1.0420","0.8020","0.5305"
"3.1800","1.0470","69.0133","1.0470","0.8059","0.5358"
"3.2000","1.0525","69.5421","1.0525","0.8101","0.5400"
"3.2200","1.0584","70.0215","1.0584","0.8146","0.5437"
"3.2400","1.0652","70.5744","1.0652","0.8199","0.5480"
"3.2600","1.0724","71.2426","1.0724","0.8254","0.5532"
"3.2800","1.0795","71.9855","1.0795","0.8309","0.5589"
"3.3000","1.0876","72.7562","1.0876","0.8371","0.5649"
"3.3200","1.0944","73.5853","1.0944","0.8424","0.5713"
"3.3400","1.0997","74.2837","1.0997","0.8465","0.5768"
"3.3600","1.1053","74.8374","1.1053","0.8508","0.5811"
"3.3800","1.1113","75.3371","1.1113","0.8554","0.5849"
"3.4000","1.1182","75.9021","1.1182","0.8607","0.5893"
"3.4200","1.1254","76.5720","1.1254","0.8662","0.5945"
"3.4400","1.1328","77.3213","1.1328","0.8720","0.6004"
"3.4600","1.1415","78.1373","1.1415","0.8786","0.6067"
"3.4800","1.1484","79.0165","1.1484","0.8839","0.6135"
"3.5000","1.1538","79.7495","1.1538","0.8881","0.6192"
"3.5090","1.1563","80.0150","1.1563","0.8900","0.6213"