File: src/instron_data/dovetailscarf.is_tens_Exports/dovetailscarf_6.csv
Time,Displacement,Force,Tensile displacement,Tensile strain (Displacement),Tensile stress
(s),(mm),(N),(mm),(%),(MPa)
"0.0000","0.0000","-0.0147","0.0000","0.0000","-0.0001"
"0.0200","0.0004","0.0073","0.0004","0.0003","0.0001"
"0.0400","0.0010","0.0622","0.0010","0.0008","0.0005"
"0.0600","0.0022","0.1315","0.0022","0.0018","0.0010"
"0.0800","0.0041","0.2480","0.0041","0.0033","0.0019"
"0.1000","0.0073","0.4414","0.0073","0.0060","0.0034"
"0.1200","0.0131","0.7580","0.0131","0.0107","0.0059"
"0.1400","0.0201","1.2664","0.0201","0.0165","0.0098"
"0.1600","0.0263","1.7279","0.0263","0.0215","0.0134"
"0.1800","0.0326","2.0400","0.0326","0.0266","0.0158"
"0.2000","0.0395","2.3234","0.0395","0.0322","0.0180"
"0.2200","0.0465","2.8439","0.0465","0.0380","0.0221"
"0.2400","0.0545","3.5614","0.0545","0.0445","0.0277"
"0.2600","0.0629","4.3392","0.0629","0.0514","0.0337"
"0.2800","0.0688","5.0225","0.0688","0.0562","0.0390"
"0.3000","0.0741","5.5837","0.0741","0.0606","0.0434"
"0.3200","0.0798","6.0589","0.0798","0.0652","0.0470"
"0.3400","0.0861","6.5137","0.0861","0.0703","0.0506"
"0.3600","0.0926","6.9770","0.0926","0.0756","0.0542"
"0.3800","0.0991","7.3890","0.0991","0.0810","0.0574"
"0.4000","0.1067","7.7999","0.1067","0.0872","0.0606"
"0.4200","0.1151","8.2543","0.1151","0.0941","0.0641"
"0.4400","0.1213","8.8762","0.1213","0.0991","0.0689"
"0.4600","0.1269","9.5827","0.1269","0.1037","0.0744"
"0.4800","0.1326","10.2860","0.1326","0.1083","0.0799"
"0.5000","0.1392","10.9728","0.1392","0.1137","0.0852"
"0.5200","0.1459","11.7300","0.1459","0.1192","0.0911"
"0.5400","0.1522","12.5173","0.1522","0.1243","0.0972"
"0.5600","0.1593","13.2928","0.1593","0.1301","0.1032"
"0.5800","0.1668","14.1044","0.1668","0.1362","0.1095"
"0.6000","0.1725","14.8926","0.1725","0.1409","0.1156"
"0.6200","0.1782","15.5768","0.1782","0.1456","0.1209"
"0.6400","0.1845","16.2341","0.1845","0.1507","0.1260"
"0.6600","0.1917","16.9307","0.1917","0.1566","0.1315"
"0.6800","0.1990","17.7465","0.1990","0.1625","0.1378"
"0.7000","0.2060","18.6090","0.2060","0.1683","0.1445"
"0.7200","0.2142","19.5124","0.2142","0.1750","0.1515"
"0.7400","0.2218","20.4970","0.2218","0.1812","0.1591"
"0.7600","0.2272","21.3641","0.2272","0.1856","0.1659"
"0.7800","0.2326","22.0925","0.2326","0.1900","0.1715"
"0.8000","0.2386","22.7646","0.2386","0.1949","0.1768"
"0.8200","0.2450","23.4938","0.2450","0.2001","0.1824"
"0.8400","0.2515","24.3128","0.2515","0.2054","0.1888"
"0.8600","0.2584","25.1750","0.2584","0.2111","0.1955"
"0.8800","0.2669","26.0954","0.2669","0.2180","0.2026"
"0.9000","0.2750","27.1742","0.2750","0.2246","0.2110"
"0.9200","0.2810","28.2148","0.2810","0.2296","0.2191"
"0.9400","0.2866","29.0701","0.2866","0.2341","0.2257"
"0.9600","0.2927","29.8129","0.2927","0.2391","0.2315"
"0.9800","0.2995","30.5779","0.2995","0.2447","0.2374"
"1.0000","0.3062","31.4128","0.3062","0.2501","0.2439"
"1.0200","0.3134","32.2731","0.3134","0.2560","0.2506"
"1.0400","0.3216","33.2034","0.3216","0.2627","0.2578"
"1.0600","0.3275","34.1585","0.3275","0.2676","0.2652"
"1.0800","0.3326","34.9231","0.3326","0.2717","0.2712"
"1.1000","0.3382","35.5401","0.3382","0.2762","0.2759"
"1.1200","0.3443","36.1518","0.3443","0.2812","0.2807"
"1.1400","0.3510","36.8524","0.3510","0.2867","0.2861"
"1.1600","0.3580","37.6439","0.3580","0.2925","0.2923"
"1.1800","0.3655","38.4980","0.3655","0.2985","0.2989"
"1.2000","0.3739","39.4073","0.3739","0.3054","0.3060"
"1.2200","0.3804","40.3565","0.3804","0.3108","0.3133"
"1.2400","0.3861","41.1055","0.3861","0.3154","0.3192"
"1.2600","0.3923","41.7362","0.3923","0.3204","0.3241"
"1.2800","0.3993","42.3835","0.3993","0.3261","0.3291"
"1.3000","0.4064","43.1316","0.4064","0.3319","0.3349"
"1.3200","0.4132","43.9207","0.4132","0.3375","0.3410"
"1.3400","0.4209","44.7141","0.4209","0.3438","0.3472"
"1.3600","0.4285","45.5256","0.4285","0.3500","0.3535"
"1.3800","0.4339","46.2710","0.4339","0.3545","0.3593"
"1.4000","0.4394","46.8187","0.4394","0.3589","0.3635"
"1.4200","0.4451","47.3116","0.4451","0.3636","0.3673"
"1.4400","0.4515","47.8551","0.4515","0.3688","0.3716"
"1.4600","0.4581","48.5035","0.4581","0.3742","0.3766"
"1.4800","0.4648","49.1967","0.4648","0.3797","0.3820"
"1.5000","0.4725","49.9285","0.4725","0.3860","0.3877"
"1.5200","0.4807","50.7679","0.4807","0.3927","0.3942"
"1.5400","0.4867","51.5756","0.4867","0.3975","0.4005"
"1.5600","0.4923","52.1887","0.4923","0.4022","0.4052"
"1.5800","0.4983","52.6903","0.4983","0.4071","0.4091"
"1.6000","0.5052","53.2331","0.5052","0.4127","0.4133"
"1.6200","0.5122","53.8953","0.5122","0.4184","0.4185"
"1.6400","0.5193","54.6566","0.5193","0.4242","0.4244"
"1.6600","0.5277","55.4745","0.5277","0.4311","0.4307"
"1.6800","0.5348","56.3925","0.5348","0.4369","0.4379"
"1.7000","0.5400","57.1591","0.5400","0.4411","0.4438"
"1.7200","0.5453","57.7015","0.5453","0.4455","0.4480"
"1.7400","0.5514","58.1918","0.5514","0.4504","0.4518"
"1.7600","0.5582","58.8071","0.5582","0.4560","0.4566"
"1.7800","0.5653","59.5913","0.5653","0.4617","0.4627"
"1.8000","0.5727","60.4639","0.5727","0.4678","0.4695"
"1.8200","0.5812","61.4392","0.5812","0.4748","0.4770"
"1.8400","0.5881","62.4765","0.5881","0.4804","0.4851"
"1.8600","0.5937","63.3533","0.5937","0.4850","0.4919"
"1.8800","0.5997","64.0683","0.5997","0.4899","0.4974"
"1.9000","0.6062","64.7677","0.6062","0.4952","0.5029"
"1.9200","0.6130","65.5509","0.6130","0.5007","0.5090"
"1.9400","0.6194","66.4119","0.6194","0.5059","0.5156"
"1.9600","0.6265","67.2812","0.6265","0.5118","0.5224"
"1.9800","0.6348","68.2590","0.6348","0.5185","0.5300"
"2.0000","0.6409","69.3154","0.6409","0.5235","0.5382"
"2.0200","0.6459","70.1691","0.6459","0.5276","0.5448"
"2.0400","0.6515","70.8415","0.6515","0.5322","0.5500"
"2.0600","0.6575","71.5070","0.6575","0.5371","0.5552"
"2.0800","0.6641","72.2810","0.6641","0.5425","0.5612"
"2.1000","0.6710","73.1770","0.6710","0.5481","0.5682"
"2.1200","0.6788","74.1938","0.6788","0.5545","0.5761"
"2.1400","0.6878","75.3759","0.6878","0.5619","0.5852"
"2.1600","0.6945","76.6506","0.6945","0.5673","0.5951"
"2.1800","0.7002","77.6933","0.7002","0.5720","0.6032"
"2.2000","0.7059","78.5092","0.7059","0.5766","0.6096"
"2.2200","0.7123","79.2653","0.7123","0.5819","0.6154"
"2.2380","0.7183","80.0322","0.7183","0.5868","0.6214"