File: src/instron_data/gooseneck.is_tens_Exports/gooseneck_2.csv
Time,Displacement,Force,Tensile displacement,Tensile strain (Displacement),Tensile stress
(s),(mm),(N),(mm),(%),(MPa)
"0.0000","0.0000","-0.0506","0.0000","0.0000","-0.0004"
"0.0200","0.0004","-0.0297","0.0004","0.0004","-0.0002"
"0.0400","0.0016","0.0253","0.0016","0.0016","0.0002"
"0.0600","0.0058","0.3256","0.0058","0.0057","0.0025"
"0.0800","0.0130","1.0872","0.0130","0.0129","0.0084"
"0.1000","0.0199","2.1473","0.0199","0.0199","0.0167"
"0.1200","0.0269","3.2224","0.0269","0.0268","0.0250"
"0.1400","0.0340","4.2325","0.0340","0.0338","0.0329"
"0.1600","0.0406","5.1950","0.0406","0.0405","0.0403"
"0.1800","0.0480","6.0800","0.0480","0.0478","0.0472"
"0.2000","0.0556","6.9426","0.0556","0.0554","0.0539"
"0.2200","0.0613","7.7043","0.0613","0.0611","0.0598"
"0.2400","0.0668","8.3368","0.0668","0.0665","0.0647"
"0.2600","0.0724","8.8995","0.0724","0.0721","0.0691"
"0.2800","0.0787","9.4958","0.0787","0.0783","0.0737"
"0.3000","0.0854","10.1775","0.0854","0.0851","0.0790"
"0.3200","0.0922","10.9431","0.0922","0.0918","0.0850"
"0.3400","0.1001","11.7505","0.1001","0.0997","0.0912"
"0.3600","0.1084","12.6280","0.1084","0.1079","0.0980"
"0.3800","0.1141","13.4627","0.1141","0.1137","0.1045"
"0.4000","0.1194","14.1219","0.1194","0.1189","0.1096"
"0.4200","0.1247","14.7031","0.1247","0.1242","0.1142"
"0.4400","0.1309","15.3040","0.1309","0.1303","0.1188"
"0.4600","0.1374","16.0278","0.1374","0.1368","0.1244"
"0.4800","0.1439","16.8228","0.1439","0.1433","0.1306"
"0.5000","0.1515","17.6404","0.1515","0.1509","0.1370"
"0.5200","0.1597","18.5516","0.1597","0.1591","0.1440"
"0.5400","0.1657","19.4139","0.1657","0.1650","0.1507"
"0.5600","0.1714","20.0561","0.1714","0.1707","0.1557"
"0.5800","0.1777","20.6139","0.1777","0.1769","0.1601"
"0.6000","0.1846","21.1495","0.1846","0.1838","0.1642"
"0.6200","0.1918","21.7141","0.1918","0.1909","0.1686"
"0.6400","0.1987","22.2368","0.1987","0.1979","0.1727"
"0.6600","0.2068","22.7263","0.2068","0.2059","0.1765"
"0.6800","0.2141","23.2714","0.2141","0.2132","0.1807"
"0.7000","0.2195","23.7210","0.2195","0.2185","0.1842"
"0.7200","0.2251","24.0541","0.2251","0.2241","0.1868"
"0.7400","0.2313","24.4433","0.2313","0.2303","0.1898"
"0.7600","0.2381","24.9347","0.2381","0.2371","0.1936"
"0.7800","0.2447","25.4909","0.2447","0.2437","0.1979"
"0.8000","0.2515","26.0597","0.2515","0.2504","0.2023"
"0.8200","0.2597","26.6538","0.2597","0.2586","0.2070"
"0.8400","0.2671","27.3438","0.2671","0.2659","0.2123"
"0.8600","0.2727","27.9536","0.2727","0.2716","0.2170"
"0.8800","0.2786","28.3731","0.2786","0.2774","0.2203"
"0.9000","0.2849","28.8263","0.2849","0.2837","0.2238"
"0.9200","0.2918","29.4619","0.2918","0.2906","0.2288"
"0.9400","0.2987","30.2039","0.2987","0.2974","0.2345"
"0.9600","0.3058","30.9653","0.3058","0.3045","0.2404"
"0.9800","0.3139","31.8023","0.3139","0.3125","0.2469"
"1.0000","0.3201","32.6539","0.3201","0.3187","0.2535"
"1.0200","0.3254","33.3697","0.3254","0.3240","0.2591"
"1.0400","0.3311","33.9638","0.3311","0.3296","0.2637"
"1.0600","0.3373","34.5863","0.3373","0.3358","0.2685"
"1.0800","0.3442","35.3433","0.3442","0.3427","0.2744"
"1.1000","0.3513","36.2435","0.3513","0.3498","0.2814"
"1.1200","0.3591","37.1844","0.3591","0.3576","0.2887"
"1.1400","0.3675","38.2521","0.3675","0.3660","0.2970"
"1.1600","0.3735","39.2732","0.3735","0.3719","0.3049"
"1.1800","0.3788","39.9866","0.3788","0.3772","0.3105"
"1.2000","0.3846","40.5518","0.3846","0.3829","0.3149"
"1.2200","0.3913","41.2157","0.3913","0.3896","0.3200"
"1.2400","0.3985","42.0945","0.3985","0.3968","0.3268"
"1.2600","0.4056","43.1338","0.4056","0.4039","0.3349"
"1.2800","0.4133","44.1985","0.4133","0.4116","0.3432"
"1.3000","0.4209","45.3571","0.4209","0.4191","0.3522"
"1.3200","0.4265","46.4107","0.4265","0.4247","0.3603"
"1.3400","0.4320","47.2050","0.4320","0.4302","0.3665"
"1.3600","0.4378","47.9322","0.4378","0.4359","0.3722"
"1.3800","0.4442","48.7247","0.4442","0.4423","0.3783"
"1.4000","0.4509","49.6722","0.4509","0.4490","0.3857"
"1.4200","0.4575","50.7086","0.4575","0.4555","0.3937"
"1.4400","0.4652","51.7551","0.4652","0.4632","0.4018"
"1.4600","0.4733","53.0172","0.4733","0.4713","0.4116"
"1.4800","0.4792","54.2683","0.4792","0.4772","0.4214"
"1.5000","0.4850","55.2099","0.4850","0.4829","0.4287"
"1.5200","0.4912","56.0415","0.4912","0.4891","0.4351"
"1.5400","0.4981","56.9813","0.4981","0.4959","0.4424"
"1.5600","0.5052","58.0989","0.5052","0.5030","0.4511"
"1.5800","0.5125","59.3124","0.5125","0.5103","0.4605"
"1.6000","0.5207","60.5644","0.5207","0.5185","0.4702"
"1.6200","0.5273","61.8689","0.5273","0.5250","0.4804"
"1.6400","0.5324","62.8928","0.5324","0.5301","0.4883"
"1.6600","0.5378","63.6228","0.5378","0.5355","0.4940"
"1.6800","0.5438","64.3903","0.5438","0.5415","0.4999"
"1.7000","0.5507","65.3742","0.5507","0.5484","0.5076"
"1.7200","0.5577","66.5893","0.5577","0.5554","0.5170"
"1.7400","0.5653","67.9006","0.5653","0.5629","0.5272"
"1.7600","0.5741","69.3535","0.5741","0.5716","0.5385"
"1.7800","0.5810","70.9169","0.5810","0.5785","0.5506"
"1.8000","0.5866","72.1739","0.5866","0.5841","0.5604"
"1.8200","0.5923","73.0812","0.5923","0.5898","0.5674"
"1.8400","0.5988","73.9527","0.5988","0.5963","0.5742"
"1.8600","0.6058","75.0065","0.6058","0.6032","0.5824"
"1.8800","0.6122","76.2047","0.6122","0.6096","0.5917"
"1.9000","0.6192","77.3968","0.6192","0.6166","0.6009"
"1.9200","0.6268","78.6986","0.6268","0.6241","0.6110"
"1.9400","0.6324","80.0012","0.6324","0.6297","0.6212"